<?xml version="1.0"?>
<robot name="robo_arm">

    <!-- Define material -->
    <material name="yellow">
        <color rgba="1.0 1.0 0.0 1" />
    </material>

    <!-- Define the origin frame 'world' -->
    <link name="world" />

    <!-- Define the robot stand -->
    <link name="robot_stand">
        <visual>
            <geometry>
                <box size="0.5 0.5 0.7" />
            </geometry>
        </visual>
    </link>

    <!-- Connect robot stand to the world with a fixed joint -->
    <joint name="world_to_robot_stand" type="fixed">
        <parent link="world" />
        <child link="robot_stand" />
        <origin xyz="0 0 0.35" rpy="0 0 0" />
    </joint>

    <!-- base link -->
    <link name="base_link">
        <visual>
            <material name="yellow" />
            <geometry>
                <cylinder radius="0.2" length="0.1" />
            </geometry>
        </visual>
    </link>

    <!-- base fixed joint -->
    <joint name="base_joint" type="fixed">
        <origin xyz="0 0 0.40" rpy="0 0 0" />
        <parent link="robot_stand" />
        <child link="base_link" />
    </joint>

    <!-- waist link -->
    <link name="waist_link">
        <visual>
            <origin xyz="0.0 0.0 0.0" rpy="1.57 0.0 0.0" />
            <material name="yellow" />
            <geometry>
                <cylinder radius="0.1" length="0.2" />
            </geometry>
        </visual>
    </link>

    <!-- Waist Joint -->
    <joint name="waist_joint" type="revolute">
        <origin xyz="0 0 0.15" rpy="0 0 0" />
        <parent link="base_link" />
        <child link="waist_link" />
        <axis xyz="0 0 1" />
        <limit lower="-3.1416" upper="3.1416" effort="1000" velocity="100" />
    </joint>

    <!-- shoulder link -->
    <link name="shoulder_link">
        <visual>
            <origin xyz="0.0 0.0 0.3" rpy="0.0 0.0 0.0" /> <!-- 0.3 is 0.2 half length + 0.1 half
            length of joint -->
            <geometry>
                <box size="0.05 0.2 0.4" />
            </geometry>
        </visual>
    </link>

    <!-- shoulder Joint -->
    <joint name="shoulder_joint" type="revolute">
        <origin xyz="0 0 0" rpy="0 0 0" />
        <parent link="waist_link" />
        <child link="shoulder_link" />
        <axis xyz="0 1 0" />
        <limit lower="-3.1416" upper="3.1416" effort="1000" velocity="100" />
    </joint>

    <!-- elbow link -->
    <link name="elbow_link">
        <visual>
            <origin xyz="0.0 0.0 0.0" rpy="1.57 0.0 0.0" />
            <material name="yellow" />
            <geometry>
                <cylinder radius="0.1" length="0.2" />
            </geometry>
        </visual>
    </link>

    <!-- elbow Joint -->
    <joint name="elbow_joint" type="revolute">
        <origin xyz="0 0 0.60" rpy="0 0 0" />
        <parent link="shoulder_link" />
        <child link="elbow_link" />
        <axis xyz="0 1 0" />
        <limit lower="-3.1416" upper="3.1416" effort="1000" velocity="100" />
    </joint>

    <!-- wrist link -->
    <link name="wrist_link">
        <visual>
            <origin xyz="0.0 0.0 0.25" rpy="0.0 0.0 0.0" /> <!-- 0.3 is 0.2 half length + 0.1 half
            length of joint -->
            <geometry>
                <box size="0.05 0.2 0.3" />
            </geometry>
        </visual>
    </link>

    <!-- fixed Joint -->
    <joint name="fixed_joint" type="fixed">
        <origin xyz="0 0 0.0" rpy="0 0 0" />
        <parent link="elbow_link" />
        <child link="wrist_link" />
    </joint>

    <!-- end effector  link -->
    <link name="ee_link">
        <visual>
            <origin xyz="0.0 0.0 0.0" rpy="1.57 0.0 0.0" />
            <material name="yellow" />
            <geometry>
                <cylinder radius="0.1" length="0.2" />
            </geometry>
        </visual>
    </link>

    <!-- wrist Joint -->
    <joint name="wrist_joint" type="revolute">
        <origin xyz="0 0 0.50" rpy="0 0 0" />
        <parent link="wrist_link" />
        <child link="ee_link" />
        <axis xyz="0 1 0" />
        <limit lower="-3.1416" upper="3.1416" effort="1000" velocity="100" />
    </joint>

    <!-- last link -->
    <link name="last_link">
        <visual>
            <origin xyz="0.0 0.0 0.15" rpy="0.0 0.0 0.0" /> <!-- 0.3 is 0.2 half length + 0.1 half
            length of joint -->
            <geometry>
                <box size="0.05 0.2 0.1" />
            </geometry>
        </visual>
    </link>

    <!-- fixed Joint -->
    <joint name="fixed_joint_2" type="fixed">
        <origin xyz="0 0 0.0" rpy="0 0 0" />
        <parent link="ee_link" />
        <child link="last_link" />
    </joint>

</robot>